init.c(556):ERROR:161: Cannot initialize TCL
Traceback (most recent call last):
  File "/home/cwang506/epigen/utils/genotype_corpus_merger.py", line 123, in merge_corpora
    self.genotype = np.append(self.genotype, np.asarray(json.load(jsonfile), dtype=np.uint8), axis=self.axis)
  File "/home/cwang506/.conda/envs/torch-env/lib/python3.8/json/__init__.py", line 293, in load
    return loads(fp.read(),
  File "/home/cwang506/.conda/envs/torch-env/lib/python3.8/json/__init__.py", line 357, in loads
    return _default_decoder.decode(s)
  File "/home/cwang506/.conda/envs/torch-env/lib/python3.8/json/decoder.py", line 337, in decode
    obj, end = self.raw_decode(s, idx=_w(s, 0).end())
  File "/home/cwang506/.conda/envs/torch-env/lib/python3.8/json/decoder.py", line 355, in raw_decode
    raise JSONDecodeError("Expecting value", s, err.value) from None
json.decoder.JSONDecodeError: Expecting value: line 1 column 1 (char 0)

During handling of the above exception, another exception occurred:

Traceback (most recent call last):
  File "merge_genotype_corpora.py", line 166, in <module>
    run_script()
  File "merge_genotype_corpora.py", line 147, in run_script
    merger.merge_corpora()
  File "/home/cwang506/epigen/utils/genotype_corpus_merger.py", line 125, in merge_corpora
    raise ValueError("Wrong array dimensions. Cannot merge along axis {}.".format(self.axis))
ValueError: Wrong array dimensions. Cannot merge along axis 0.
